Workbook

Sheet INDEX
A1: SINOKOR DOCKING REQUISITION INDEX
A2: OWNER | C2: SINOKOR MARITIME | E2: VESSEL NAME | G2: SOUTH AFRICA PROSPERITY
A3: TYPE OF VESSEL | C3: VLCC | E3: KIND OF SURVEY | G3: 3RD SPECIAL SURVEY
A4: SHIPYARD | C4: SHEKOU CHINA OR ZHOUSHAN CHINA | E4: DUE DATE | G4: 46244
A5: No. | B5: REQ. NUMBER | C5: CATEGORY | D5: EQUIPMENT | E5: SUBJECT | F5: PREPARED BY | G5: LINK | H5: REMARK
A6: 1 | B6: R1 | C6: SHORE REPAIR | D6: MAIN ENGINE | E6: M/E OVHL | F6: OWNER | G6: R1
A7: 2 | B7: R2 | C7: SHORE REPAIR | D7: MAIN ENGINE T/C | E7: M/E T/C OVHL | F7: OWNER | G7: R2
A8: 3 | B8: R3 | C8: SHORE REPAIR | D8: MAIN ENGINE | E8: M/E PNEUMATIC SYSTEM OVHL | F8: OWNER | G8: R3
A9: 4 | B9: R4 | C9: SHORE REPAIR | D9: MAIN ENGINE LUBRICATOR | E9: M/E ALPHA LUBRICATOR OVHL | F9: OWNER | G9: R4
A10: 5 | B10: R5 | C10: SHORE REPAIR | D10: AUX ENGINE | E10: A/E OVHL | F10: OWNER | G10: R5
A11: 6 | B11: R6 | C11: SHORE REPAIR | D11: AUX ENGINE T/C | E11: A/E T/C OVHL | F11: OWNER | G11: R6
A12: 7 | B12: R7 | C12: SHORE REPAIR | D12: AUX ENGINE GOVERNOR | E12: A/E GOVERNOR OVHL | F12: OWNER | G12: R7
A13: 8 | B13: R8 | C13: SHORE REPAIR | D13: AUX BOILER | E13: AUX BOILER HEALTH CHECK | F13: OWNER | G13: R8
A14: 9 | B14: R9 | C14: SHORE REPAIR | D14: BWTS | E14: BWTS HEALTH CHECK | F14: OWNER | G14: R9
A15: 10 | B15: R10 | C15: SHORE REPAIR | D15: STERN TUBE | E15: STERN TUB SEAL SERVICE | F15: OWNER | G15: R10
A16: 11 | B16: R11 | C16: SHORE REPAIR | D16: ICCP | E16: ICCP SERVICE | F16: OWNER | G16: R11
A17: 12 | B17: R12 | C17: SHORE REPAIR | D17: PLATE COOLER | E17: PLATE COOLER CLEANING | F17: OWNER | G17: R12
... A21: 16 | B21: R16 | C21: SHORE REPAIR | D21: VRC & WBT LEVEL SYSTEM | E21: VRC & WBT LEVEL SYSTEM HEALTH CHECK | F21: OWNER | G21: R16
A22: 17 | B22: R17 | C22: SHORE REPAIR | D22: COT LEVEL SENSOR | E22: COT RADAR LEVEL SENSOR HEALTH CHECK | F22: MANAGER | G22: R17 | H22: Krohne
A23: 18 | B23: R18 | C23: SHORE REPAIR | D23: VARIOUS SENSOR EQUIPMENT | E23: VARIOUS SENSOR EQUIPMENT HEALTH CHECK | F23: OWNER | G23: R18
A24: 19 | B24: R19 | C24: SHORE REPAIR | D24: ODME | E24: ODME CALIBRATION | F24: MANAGER | G24: R19 | H24: VAF
A25: 20 | B25: R20 | C25: SHORE REPAIR | D25: Deck Crane | E25: HH Crane & Provision Crane // ER Crane Health Check | F25: OWNER | G25: R20
A26: 21 | B26: R21 | C26: SHORE REPAIR | D26: Steering Gear | E26: Steering Gear Hydraulic System Health Check | F26: OWNER | G26: R21
A27: 22 | B27: R22 | C27: SHORE REPAIR | D27: Safety Equipement | E27: LSA & FFE | F27: OWNER | G27: R22
A28: 23 | B28: R23 | C28: SHORE REPAIR | D28: Navigation Equipment | E28: Radia Survey | F28: OWNER | G28: R23
A29: 24 | B29: R24 | C29: SHORE REPAIR | D29: ELEVATOR | E29: Elevator Annual Service | F29: MANAGER | G29: R24
A30: 25 | B30: R25 | C30: SHORE REPAIR | D30: INERT GAS SYSTEM | E30: IGS System Health Check | F30: OWNER | G30: R25
A31: 26 | B31: R26 | C31: SHORE REPAIR | D31: COPT & WBPT GOVERNOR | E31: COPT & WBPT Governor Maintenance | F31: OWNER | G31: R26
A32: 27 | B32: R27 | C32: SHORE REPAIR | D32: Windlass | E32: Windlass Hydraulic System Health Check | F32: OWNER | G32: R27
A33: 28 | C33: SHORE REPAIR | F33: OWNER | G33: R28
A34: 29 | C34: SHORE REPAIR | F34: OWNER | G34: R29
A35: 30 | C35: SHORE REPAIR | F35: OWNER | G35: R30
A36: 31 | C36: SHORE REPAIR | F36: OWNER | G36: R31
A37: 28 | B37: S1 | C37: SPARE | D37: MAIN ENGINE | E37: MAIN ENGINE OVHL SPARE | F37: OWNER | G37: S1
A38: 29 | B38: S2 | C38: SPARE | D38: MAIN ENGINE | E38: M/E F.O PUMP OVHL SPARE | F38: OWNER | G38: S2
A39: 30 | B39: S3 | C39: SPARE | D39: MAIN ENGINE | E39: M/E T/C OVHL SPARE | F39: OWNER | G39: S3
A40: 31 | B40: S4 | C40: SPARE | D40: MAIN ENGINE | E40: M/E AIR COOLER SPARE | F40: OWNER | G40: S4
A41: 32 | B41: S5 | C41: SPARE | D41: MAIN ENGINE | E41: M/E AUX BLOWER SPARE | F41: OWNER | G41: S5
A42: 33 | B42: S6 | C42: SPARE | D42: AUX ENGINE | E42: AUX ENGINE OVHL SPARE | F42: OWNER | G42: S6
A43: 34 | B43: S7 | C43: SPARE | D43: AUX ENGINE | E43: AUX ENGINE T/C OVHL SPARE | F43: OWNER | G43: S7
...

Sheet R1
A1: SINOKOR DOCKING SHORE REPAIR REQUISITION FORM | H1: ← INDEX
A3: OWNER | C3: =INDEX!C2 -> SINOKOR MARITIME | E3: PREPARED BY | G3: OWNER
A4: VESSEL | C4: =INDEX!G2 -> SOUTH AFRICA PROSPERITY | E4: REQ. NO. | G4: R1
A5: EQUIPMENT | C5: MAIN ENGINE | E5: SERIAL NO.
A6: MAKER | C6: HYUNDAI B&W | E6: TYPE | G6: 6S90MC-C7
A7: SUBJECT | C7: M/E OVHL
A9: ITEM LIST
A10: No. | B10: JOB SCOPE | E10: UNIT | F10: Q.Ty | G10: REMARK
A11: 1 | B11: M/E OVERHAUL
A12: 2 | B12: PISTON OVERHAUL | E12: CYL | F12: 6
A13: 3 | B13: PISTON ROD STUFFING BOX OVERHAUL | E13: CYL | F13: 6
A14: 4 | B14: CROSS HEAD BEARING OVERHAUL | E14: CYL | F14: 2 | G14: CLASS SURVEY
A15: 5 | B15: CRANK PIN BEARING OVERHAUL | E15: CYL | F15: 2 | G15: CLASS SURVEY
A16: 6 | B16: MAIN BEARING OVERHAUL | E16: CYL | F16: 2 | G16: CLASS SURVEY
A17: 7 | B17: THRUST BEARING OVERHAUL | E17: CYL | F17: 1 | G17: CLASS SURVEY
A18: 8 | B18: F.O PUMP OVHL | E18: CYL | F18: 6
A19: 9 | B19: CYLINDER LINER RENEWAL (IF NEED) | E19: CYL | F19: 1
A20: 10 | B20: CYLINDER COVER OVHL (EXH. VALVE / F.I.V / STARTING VALVE) (IF NEED) | E20: CYL | F20: 1
A21: 11 | B21: SEATRIAL | E21: LOT | F21: 1
A22: 12
A23: 13
A24: 14
A25: 15
A26: 16
A27: 17
A28: 18
A29: 19
A30: 20
A31: 21
A32: 22
A33: 23
... A40: 30

Sheet R2
A1: SINOKOR DOCKING SHORE REPAIR REQUISITION FORM | H1: ← INDEX
A3: OWNER | C3: =INDEX!C2 -> SINOKOR MARITIME | E3: PREPARED BY | G3: OWNER
A4: VESSEL | C4: =INDEX!G2 -> SOUTH AFRICA PROSPERITY | E4: REQ. NO. | G4: R2
A5: EQUIPMENT | C5: MAIN ENGINE | E5: SERIAL NO.
A6: MAKER | C6: HYUNDAI MITSUBISHI | E6: TYPE | G6: MET71MA
A7: SUBJECT | C7: M/E T/C OVHL
A9: ITEM LIST
A10: No. | B10: JOB SCOPE | E10: UNIT | F10: Q.Ty | G10: REMARK
A11: 1 | B11: M/E TURBO CHARGER OVHL | E11: LOT | F11: 2
A12: 2 | B12: Dismantle Silencer, air inlet casing and draw out Rotoer, clean in place,
A13: 3 | B13: Check all parts condition and renew parts if necessary,
A14: 4 | B14: Reassemble rotor, air inlet casing and silencer,
A15: 5 | B15: Check the measured points and report,
A16: 6 | B16: Dismantle, clean and reassemble gas Inlet Inner Casing.
A17: 7 | B17: Dismantle and reassemble nozzle ring
A18: 8
A19: 9
A20: 10
A21: 11
A22: 12
A23: 13
A24: 14
A25: 15
A26: 16
A27: 17
A28: 18
A29: 19
... A40: 30

Sheet R3
A1: SINOKOR DOCKING SHORE REPAIR REQUISITION FORM | H1: ← INDEX
A3: OWNER | C3: =INDEX!C2 -> SINOKOR MARITIME | E3: PREPARED BY | G3: OWNER
A4: VESSEL | C4: =INDEX!G2 -> SOUTH AFRICA PROSPERITY | E4: REQ. NO. | G4: R3
A5: EQUIPMENT | C5: MAIN ENGINE | E5: SERIAL NO.
A6: MAKER | C6: HYUNDAI B&W | E6: TYPE | G6: 6S90MC-C7
A7: SUBJECT | C7: M/E PNEUMATIC SYSTEM OVHL
A9: ITEM LIST
A10: No. | B10: JOB SCOPE | E10: UNIT | F10: Q.Ty | G10: REMARK
A11: 1 | B11: M/E PNEUMATIC SYSTEM TOTAL OVERHAUL | E11: LOT | F11: 1 | G11: 5 YEAR SERVICE
A12: 2 | B12: 1) Pneumatic valves overhaul (Full Scope)
A13: 3 | B13: 2) ME Engine related all cables, cable sensors Inspection
A14: 4 | B14: 3) Engine Test
A15: 5
A16: 6
A17: 7
A18: 8
A19: 9
A20: 10
A21: 11
A22: 12
A23: 13
A24: 14
A25: 15
A26: 16
... A40: 30

Sheet R4
A1: SINOKOR DOCKING SHORE REPAIR REQUISITION FORM | H1: ← INDEX
A3: OWNER | C3: =INDEX!C2 -> SINOKOR MARITIME | E3: PREPARED BY | G3: OWNER
A4: VESSEL | C4: =INDEX!G2 -> SOUTH AFRICA PROSPERITY | E4: REQ. NO. | G4: R4
A5: EQUIPMENT | C5: MAIN ENGINE LUBRICATOR | E5: SERIAL NO.
A6: MAKER | C6: HYUNDAI B&W | E6: TYPE | G6: 6S90MC-C7
A7: SUBJECT | C7: M/E ALPHA LUBRICATOR OVHL
A9: ITEM LIST
A10: No. | B10: JOB SCOPE | E10: UNIT | F10: Q.Ty | G10: REMARK
A11: 1 | B11: M/E ALPHA LUB SYSTEM OVHL | E11: LOT | F11: 1 | G11: 5 YEAR SERVICE
A12: 2 | B12: M/E ALPHA LUB SYSTEM OVHL KIT SUPPLY | E12: SET | F12: 1
A13: 3
A14: 4
A15: 5
A16: 6
A17: 7
A18: 8
A19: 9
A20: 10
A21: 11
A22: 12
A23: 13
A24: 14
... A40: 30

Sheet R5
A1: SINOKOR DOCKING SHORE REPAIR REQUISITION FORM | H1: ← INDEX
A3: OWNER | C3: =INDEX!C2 -> SINOKOR MARITIME | E3: PREPARED BY | G3: OWNER
A4: VESSEL | C4: =INDEX!G2 -> SOUTH AFRICA PROSPERITY | E4: REQ. NO. | G4: R5
A5: EQUIPMENT | C5: AUX ENGINE | E5: SERIAL NO.
A6: MAKER | C6: HYUNDAI HIMSEN | E6: TYPE | G6: 7H21/32
A7: SUBJECT | C7: A/E OVHL
A9: ITEM LIST
A10: No. | B10: JOB SCOPE | E10: UNIT | F10: Q.Ty | G10: REMARK
A11: 1 | B11: A/E OVERHAUL | E11: SET | F11: 1
A12: 2 | B12: CYLINDER HEAD OVERHAUL & MAINTENANCE | E12: INCL.
A13: 3 | B13: PISTON & CONNECTING ROD OVERHAUL | E13: INCL.
A14: 4 | B14: CYLINDER LINER OVERHAUL ( IF NEED ) | E14: CYL
A15: 5 | B15: FUEL INJECTION PUMP (IF NEED) | E15: CYL
A16: 6 | B16: CAMSHAFT BEARING CLEARANCE CHECK (IF NEED ) | E16: CYL
A17: 7 | B17: MAIN BEARING CLEARANCE CHECK (IF NEED ) | E17: CYL
A18: 8 | B18: MAIN BEARING OVERHAUL (IF NEED ) | E18: CYL
A19: 9 | B19: SUMP TANK & CRANK CHAMBER CLEAN | E19: SET | F19: 1
A20: 10 | B20: CRANK SHAFT DEFLECTION CHECK | E20: SET | F20: 1
A21: 11 | B21: TRIAL RUNNING | E21: SET | F21: 1
A22: 12
A23: 13
A24: 14
A25: 15
A26: 16
A27: 17
A28: 18
A29: 19
A30: 20
A31: 21
A32: 22
A33: 23
... A40: 30

Sheet R6
A1: SINOKOR DOCKING SHORE REPAIR REQUISITION FORM | H1: ← INDEX
A3: OWNER | C3: =INDEX!C2 -> SINOKOR MARITIME | E3: PREPARED BY | G3: OWNER
A4: VESSEL | C4: =INDEX!G2 -> SOUTH AFRICA PROSPERITY | E4: REQ. NO. | G4: R6
A5: EQUIPMENT | C5: AUX ENGINE | E5: SERIAL NO.
A6: MAKER | C6: ABB | E6: TYPE | G6: TPS52D01
A7: SUBJECT | C7: A/E T/C OVHL
A9: ITEM LIST
A10: No. | B10: JOB SCOPE | E10: UNIT | F10: Q.Ty | G10: REMARK
A11: 1 | B11: G/E TURBO CHARGER OVHL | E11: LOT | F11: 3
A12: 2 | B12: Dismantle silencer, compressor casing, catridge and cleaning,
A13: 3 | B13: Reassemble catridge,compressor casing, silencer
A14: 4 | B14: Check the measure points and report
A15: 5 | B15: Dismantle Compressor wheel, draw out rotor and dismantle
A16: 6 | B16: moving parts, clean in place. Inspect and measure all parts
A17: 7 | B17: reassemble all parts. Renew spares if necessary
A18: 8 | B18: Dismantle, inspect and reassemble Nozzle ring
A19: 9
A20: 10
A21: 11
A22: 12
A23: 13
A24: 14
A25: 15
A26: 16
A27: 17
A28: 18
A29: 19
A30: 20
... A40: 30

Sheet R7
A1: SINOKOR DOCKING SHORE REPAIR REQUISITION FORM | H1: ← INDEX
A3: OWNER | C3: =INDEX!C2 -> SINOKOR MARITIME | E3: PREPARED BY | G3: OWNER
A4: VESSEL | C4: =INDEX!G2 -> SOUTH AFRICA PROSPERITY | E4: REQ. NO. | G4: R7
A5: EQUIPMENT | C5: AUX ENGINE | E5: SERIAL NO.
A6: MAKER | C6: WOODWARD | E6: TYPE | G6: UG-25+
A7: SUBJECT | C7: A/E GOVERNOR OVHL
A9: ITEM LIST
A10: No. | B10: JOB SCOPE | E10: UNIT | F10: Q.Ty | G10: REMARK
A11: 1 | B11: G/E GOVERNOR OVHL | E11: SET | F11: 3
A12: 2 | B12: OVHL kit supply | E12: SET | F12: 3
A13: 3 | B13: Trial Running | E13: INCL.
A14: 4
A15: 5
A16: 6
A17: 7
A18: 8
A19: 9
A20: 10
A21: 11
A22: 12
A23: 13
A24: 14
A25: 15
... A40: 30

Sheet R8
A1: SINOKOR DOCKING SHORE REPAIR REQUISITION FORM | H1: ← INDEX
A3: OWNER | C3: =INDEX!C2 -> SINOKOR MARITIME | E3: PREPARED BY | G3: OWNER
A4: VESSEL | C4: =INDEX!G2 -> SOUTH AFRICA PROSPERITY | E4: REQ. NO. | G4: R8
A5: EQUIPMENT | C5: AUX BOILER | E5: SERIAL NO.
A6: MAKER | C6: AALBORG | E6: TYPE | G6: MISSION D-TYPE
A7: SUBJECT | C7: AUX BOILER HEALTH CHECK
A9: ITEM LIST
A10: No. | B10: JOB SCOPE | E10: UNIT | F10: Q.Ty | G10: REMARK
A11: 1 | B11: AUX BOILER HEALTH CHECK | E11: LOT | F11: 2 | G11: 5 YEAR SERVICE
A12: 2 | B12: BURNER MAINTENANCE
A13: 3 | B13: ACC SYSTEM CHECK
A14: 4 | B14: BCC SYSTEM CHECK
A15: 5 | B15: SAFETY SYSTEM CHECK
A16: 6 | B16: LEVEL CONTROL SYSTEM CHECK
A17: 7
A18: 8
A19: 9
A20: 10
A21: 11
A22: 12
A23: 13
A24: 14
A25: 15
A26: 16
A27: 17
A28: 18
... A40: 30

Sheet R9
A1: SINOKOR DOCKING SHORE REPAIR REQUISITION FORM | H1: ← INDEX
A3: OWNER | C3: =INDEX!C2 -> SINOKOR MARITIME | E3: PREPARED BY | G3: OWNER
A4: VESSEL | C4: =INDEX!G2 -> SOUTH AFRICA PROSPERITY | E4: REQ. NO. | G4: R9
A5: EQUIPMENT | C5: BWTS | E5: SERIAL NO.
A6: MAKER | C6: ERMA FIRST BWTS | E6: TYPE | G6: FIT-2X3000-EX
A7: SUBJECT | C7: BWTS HEALTH CHECK
A9: ITEM LIST
A10: No. | B10: JOB SCOPE | E10: UNIT | F10: Q.Ty | G10: REMARK
A11: 1 | B11: BWTS HEALTH CHECK | E11: LOT | F11: 1 | G11: 5 YEAR SERVICE
A12: 2
A13: 3
A14: 4
A15: 5
A16: 6
A17: 7
A18: 8
A19: 9
A20: 10
A21: 11
A22: 12
A23: 13
... A40: 30

Sheet R10
A1: SINOKOR DOCKING SHORE REPAIR REQUISITION FORM | H1: ← INDEX
A3: OWNER | C3: =INDEX!C2 -> SINOKOR MARITIME | E3: PREPARED BY | G3: OWNER
A4: VESSEL | C4: =INDEX!G2 -> SOUTH AFRICA PROSPERITY | E4: REQ. NO. | G4: R10
A5: EQUIPMENT | C5: STERN TUBE | E5: SERIAL NO. | G5: X-39128
A6: MAKER | C6: KEMEL | E6: TYPE | G6: AX-900
A7: SUBJECT | C7: STERN TUB SEAL SERVICE
A9: ITEM LIST
A10: No. | B10: JOB SCOPE | E10: UNIT | F10: Q.Ty | G10: REMARK
A11: 1 | B11: STERN TUBE SEAL RENEWAL (FWD/ AFT) | E11: LOT | F11: 1
A12: 2
A13: 3
A14: 4
A15: 5
A16: 6
A17: 7
A18: 8
A19: 9
A20: 10
A21: 11
A22: 12
A23: 13
... A40: 30

Sheet R11
A1: SINOKOR DOCKING SHORE REPAIR REQUISITION FORM | H1: ← INDEX
A3: OWNER | C3: =INDEX!C2 -> SINOKOR MARITIME | E3: PREPARED BY | G3: OWNER
A4: VESSEL | C4: =INDEX!G2 -> SOUTH AFRICA PROSPERITY | E4: REQ. NO. | G4: R11
A5: EQUIPMENT | C5: ICCP | E5: SERIAL NO. | G5: 5234/A
A6: MAKER | C6: KC | E6: TYPE | G6: AFT KCIT 790A / FWD KCIT 720A
A7: SUBJECT | C7: ICCP SERVICE
A9: ITEM LIST
A10: No. | B10: JOB SCOPE | E10: UNIT | F10: Q.Ty | G10: REMARK
A11: 1 | B11: ICCP ANODE & REF. CELL RENEWAL | E11: LOT | F11: 1 | G11: 5 YEAR SERVICE
A12: 2
A13: 3
A14: 4
A15: 5
A16: 6
A17: 7
A18: 8
A19: 9
A20: 10
A21: 11
A22: 12
A23: 13
... A40: 30

Sheet R12
A1: SINOKOR DOCKING SHORE REPAIR REQUISITION FORM | H1: ← INDEX
A3: OWNER | C3: =INDEX!C2 -> SINOKOR MARITIME | E3: PREPARED BY | G3: OWNER
A4: VESSEL | C4: =INDEX!G2 -> SOUTH AFRICA PROSPERITY | E4: REQ. NO. | G4: R12
A5: EQUIPMENT | C5: PLATE COOLER | E5: SERIAL NO. | G5: 30113-66568/9, 30113-66570/1
A6: MAKER | C6: ALFAL LAVAL | E6: TYPE | G6: MX25-MFMS
A7: SUBJECT | C7: PLATE COOLER CLEANING
A9: ITEM LIST
A10: No. | B10: JOB SCOPE | E10: UNIT | F10: Q.Ty | G10: REMARK
A11: 1 | B11: MAIN L.O COOLER CLEANING & GASKET RENEWAL (TO BE SUPPLIED) | E11: LOT | F11: 2
A12: 2 | B12: MAKER : ALFA LAVAL
A13: 3 | B13: TYPE : MX25-MFMS
A14: 4 | B14: NO. OF PLATES : 209
A15: 5
A16: 6 | B16: CENTRAL F.W COOLER CLEANING & GASKET RENEWAL (TO BE SUPPLIED) | E16: LOT | F16: 2
A17: 7 | B17: MAKER : ALFA LAVAL
A18: 8 | B18: TYPE : MX25-MFMS
A19: 9 | B19: NO. OF PLATES : 196+1
A20: 10
A21: 11
A22: 12
A23: 13
A24: 14
A25: 15
A26: 16
A27: 17
A28: 18
A29: 19
A30: 20
A31: 21
... A40: 30

Sheet R13
A1: SINOKOR DOCKING SHORE REPAIR REQUISITION FORM | H1: ← INDEX
A3: OWNER | C3: =INDEX!C2 -> SINOKOR MARITIME | E3: PREPARED BY | G3: OWNER
A4: VESSEL | C4: =INDEX!G2 -> SOUTH AFRICA PROSPERITY | E4: REQ. NO. | G4: R13
A5: EQUIPMENT | C5: UT GAUGING | E5: SERIAL NO.
A6: MAKER | E6: TYPE
A7: SUBJECT | C7: UT GAUGING
A9: ITEM LIST
A10: No. | B10: JOB SCOPE | E10: UNIT | F10: Q.Ty | G10: REMARK
A11: 1 | B11: ULTRASONIC THICKNESS MEASUREMENT | E11: LOT | F11: 1 | G11: 15 YEARS / 3RD SPECIAL / BV CLASS
A12: 2 | B12: VLCC CAP SURVEY | E12: LOT | F12: 1
A13: 3
A14: 4
A15: 5
A16: 6
A17: 7
A18: 8
A19: 9
A20: 10
A21: 11
A22: 12
A23: 13
A24: 14
... A40: 30

Sheet R14
A1: SINOKOR DOCKING SHORE REPAIR REQUISITION FORM | H1: ← INDEX
A3: OWNER | C3: =INDEX!C2 -> SINOKOR MARITIME | E3: PREPARED BY | G3: OWNER
A4: VESSEL | C4: =INDEX!G2 -> SOUTH AFRICA PROSPERITY | E4: REQ. NO. | G4: R14
A5: EQUIPMENT | C5: COT ROPE ACCESS | E5: SERIAL NO.
A6: MAKER | E6: TYPE
A7: SUBJECT | C7: COT ROPE ACCESS
A9: ITEM LIST
A10: No. | B10: JOB SCOPE | E10: UNIT | F10: Q.Ty | G10: REMARK
A11: 1 | B11: VLCC COT ROPE ACCESS FOR CAP SURVEY | E11: LOT | F11: 1 | G11: 15 YEARS / 3RD SPECIAL SURVEY / BV CLASS
A12: 2
A13: 3
A14: 4
A15: 5
A16: 6
A17: 7
A18: 8
A19: 9
A20: 10
A21: 11
A22: 12
A23: 13
... A40: 30

Sheet R15
A1: SINOKOR DOCKING SHORE REPAIR REQUISITION FORM | H1: ← INDEX
A3: OWNER | C3: =INDEX!C2 -> SINOKOR MARITIME | E3: PREPARED BY | G3: OWNER
A4: VESSEL | C4: =INDEX!G2 -> SOUTH AFRICA PROSPERITY | E4: REQ. NO. | G4: R15
A5: EQUIPMENT | C5: ELECTRIC | E5: SERIAL NO.
A6: MAKER | C6: HYUNDAI | E6: TYPE
A7: SUBJECT | C7: ELECTRIC SERVICE
A9: ITEM LIST
A10: No. | B10: JOB SCOPE | E10: UNIT | F10: Q.Ty | G10: REMARK
A11: 1 | B11: MSBD CLEANING, PIECE RETIGHTENING | E11: LOT | F11: 1 | G11: HYUNDAI
A12: 2 | B12: ESBD CLEANING, PIECE RETIGHTENING | E12: LOT | F12: 1 | G12: HYUNDAI
A13: 3 | B13: A.C.B OVERHAUL & TEST | E13: SET | F13: 7 | G13: HYUNDAI (HiAN-20,08,40, AME-6B)
A14: 4 | B14: GENERATOR COIL CHEMICAL CLEANING & AVR UNIT CHECK | E14: SET | F14: 3 | G14: HYUNDAI
A15: 5 | B15: 440V/220V TRANSFORMER CLEANING | E15: SET | F15: 5 | G15: HYUNDAI (150kVA x 2 70kVA x2 25kVA x1)
A16: 6 | B16: DC24 BATTERY CHARGER GENERAL CHECK | E16: SET | F16: 1 | G16: SEUN ELECTRIC (DC24V, 70A)
A17: 7 | B17: M/E SAFETY DEVICE TEST | E17: LOT | F17: 1 | G17: MAN B&W 6S90MC-C7
A18: 8 | B18: A/E SAFETY DEVICE TEST | E18: LOT | F18: 1 | G18: HYUNDAI HIMSEN 7H21/32
A19: 9 | B19: A/E PMS SYSTEM TEST | E19: LOT | F19: 1 | G19: HYUNDAI ACONIS-2000 PMS
A20: 10 | B20: ALARM MONITORING SYSTEM CHECK | E20: LOT | F20: 1 | G20: HYUNDAI ACONIS-2000
A21: 11 | B21: BLACK OUT TEST | E21: LOT | F21: 1 | G21: CLASS SURVEY
A22: 12 | B22: MEGGER TEST & IMPROVE | E22: LOT | F22: 1
A23: 13
A24: 14
A25: 15
A26: 16
A27: 17
A28: 18
A29: 19
A30: 20
A31: 21
A32: 22
A33: 23
A34: 24
... A40: 30

Sheet R16
A1: SINOKOR DOCKING SHORE REPAIR REQUISITION FORM | H1: ← INDEX
A3: OWNER | C3: =INDEX!C2 -> SINOKOR MARITIME | E3: PREPARED BY | G3: OWNER
A4: VESSEL | C4: =INDEX!G2 -> SOUTH AFRICA PROSPERITY | E4: REQ. NO. | G4: R16
A5: EQUIPMENT | C5: VRC & WBT LEVEL SYSTEM | E5: SERIAL NO.
A6: MAKER | C6: SCANA KOREA | E6: TYPE | G6: HYD. TYPE
A7: SUBJECT | C7: VRC & WBT LEVEL SYSTEM HEALTH CHECK
A9: ITEM LIST
A10: No. | B10: JOB SCOPE | E10: UNIT | F10: Q.Ty | G10: REMARK
A11: 1 | B11: Valve Remote Control system | E11: Lot | F11: 1 | G11: Maker : Scana Korea
A12: 2 | B12: - HPU to be checked & adjusted & repaired | G12: 300 Ltr, 2 Set Hyd. Pump, 130 Bar
A13: 3 | B13: - Cargo & Ballast valve system to be checked & adjusted & repaired
A14: 4 | B14: - Actuator to be checked and adjsuted | E14: Set | F14: 95
A15: 5 | B15: - To be cooperated with Shipyard, in case seat ring renewal
A16: 6 | B16: WBT & Draft Level system | E16: Lot | F16: 1 | G16: Maker : HANLA IMS
A17: 7 | B17: - WBT & Draft level system to be checked
A18: 8 | B18: - Purge unit to be cleaned and overhauled, Gauge to be calibrated | E18: set | F18: 16
A19: 9 | B19: - Signal line to be checked
A20: 10 | B20: CCR & Pump room gauge | E20: Lot | F20: 1
A21: 11 | B21: - Pump suct & disch. Pressure gauge & transmitter to be calibrated
A22: 12 | B22: - Signal line to be checked
A23: 13 | B23: Auto Unloading system | E23: Lot | F23: 1
A24: 14 | B24: - AUS System to be checked | E24: set | F24: 3
A25: 15 | B25: - Discharge valve & Separator level to be adjusted and calibrated
A26: 16 | B26: - GEV Valve to be adjusted and calibrated
A27: 17
A28: 18
A29: 19
A30: 20
A31: 21
A32: 22
A33: 23
A34: 24
A35: 25
A36: 26
A37: 27
A38: 28
... A40: 30

Sheet R17
A1: SINOKOR DOCKING SHORE REPAIR REQUISITION FORM | H1: ← INDEX
A3: OWNER | C3: =INDEX!C2 -> SINOKOR MARITIME | E3: PREPARED BY | G3: OWNER
A4: VESSEL | C4: =INDEX!G2 -> SOUTH AFRICA PROSPERITY | E4: REQ. NO. | G4: R17
A5: EQUIPMENT | C5: COT LEVEL SENSOR | E5: SERIAL NO.
A6: MAKER | C6: KROHNE | E6: TYPE | G6: Radar Beam type
A7: SUBJECT | C7: COT LEVEL SENSOR HEALTH CHECK
A9: ITEM LIST
A10: No. | B10: JOB SCOPE | E10: UNIT | F10: Q.Ty | G10: REMARK
A11: 1 | B11: COT Level Sensor Health Check | E11: Lot | F11: 1
A12: 2 | B12: - Radar Ullage Reading to be checked & Calibrated
A13: 3 | B13: - Temprature Reading to be checked & Calibrated
A14: 4 | B14: - IG Pressure Reading to be checked & Calibrated
A15: 5 | B15: - COT Sysetm to be checked
A16: 6
A17: 7
A18: 8
A19: 9
A20: 10
A21: 11
A22: 12
A23: 13
A24: 14
A25: 15
A26: 16
A27: 17
... A40: 30

Sheet R18
A1: SINOKOR DOCKING SHORE REPAIR REQUISITION FORM | H1: ← INDEX
A3: OWNER | C3: =INDEX!C2 -> SINOKOR MARITIME | E3: PREPARED BY | G3: OWNER
A4: VESSEL | C4: =INDEX!G2 -> SOUTH AFRICA PROSPERITY | E4: REQ. NO. | G4: R18
A5: EQUIPMENT | C5: VARIOUS SENSOR EQUIPMENT | E5: SERIAL NO.
A6: MAKER | E6: TYPE
A7: SUBJECT | C7: VARIOUS SENSOR EQUIPMENT HEALTH CHECK
A9: ITEM LIST
A10: No. | B10: JOB SCOPE | E10: UNIT | F10: Q.Ty | G10: REMARK
A11: 1 | B11: Fixed Gas Detection system | E11: Lot | F11: 1 | G11: Maker : Consilium (SW2020)
A12: 2 | B12: - System to be checked
A13: 3 | B13: - Sampling line to be checked | E13: lines | F13: 32
A14: 4 | B14: - Detector to be checked and calibrated (O2, H2S, HC)
A15: 5 | B15: Manifold Pressure Monitoring system | E15: Lot | F15: 1 | G15: Maker : HANLA IMS
A16: 6 | B16: - System to be checked
A17: 7 | B17: - Pressure Transmeter Cabinet to be checked and calibrated
A18: 8 | B18: COT Overfill Alarm | E18: Lot | F18: 1 | G18: Maker : PANASIA
A19: 9 | B19: - System to be checked
A20: 10 | B20: - Level S/W to be checked and calibrated | E20: set | F20: 23
A21: 11 | B21: M/E OMD System | E21: Lot | F21: 1 | G21: Maker : Visatron VN215
A22: 12 | B22: - System to be checked
A23: 14 | B23: - Calibration cert. to be provided
A24: 15 | B24: OWS 15 PPM | E24: Lot | F24: 1 | G24: Maker :GEORIM Engineering GBA-155
A25: 16 | B25: - System to be checked
A26: 17 | B26: - Calibration cert. to be provided
A27: 18 | B27: IGS O2 Analyzer | E27: Lot | F27: 1 | G27: Maker : Energy support corp. TF-SR
A28: 19 | B28: - System to be checked | E28: set | F28: 2
A29: 20 | B29: - Calibration cert. to be provided
A30: 21 | B30: Fire detection System | E30: Lot | F30: 1 | G30: Maker : Consilium SALWICO CS4000
A31: 22 | B31: - System to be checked
A32: 23 | B32: - Sensor to be tested and repaired
A33: 24
A34: 25
A35: 26
A36: 27
A37: 28
A38: 29
A39: 30

Sheet R19
A1: SINOKOR DOCKING SHORE REPAIR REQUISITION FORM | H1: ← INDEX
A3: OWNER | C3: =INDEX!C2 -> SINOKOR MARITIME | E3: PREPARED BY | G3: OWNER
A4: VESSEL | C4: =INDEX!G2 -> SOUTH AFRICA PROSPERITY | E4: REQ. NO. | G4: R19
A5: EQUIPMENT | C5: ODME | E5: SERIAL NO.
A6: MAKER | C6: VAF INSTRUMENTS | E6: TYPE | G6: OILCON MARK 6M
A7: SUBJECT | C7: ODME CALIBRATION
A9: ITEM LIST
A10: No. | B10: JOB SCOPE | E10: UNIT | F10: Q.Ty | G10: REMARK
A11: 1 | B11: ODME 5 Year Calibration to be carried out | E11: LOT | F11: 1
A12: 2 | B12: Certificate to be provided
A13: 3
A14: 4
A15: 5
A16: 6
A17: 7
A18: 8
A19: 9
A20: 10
A21: 11
A22: 12
A23: 13
A24: 14
... A40: 30

Sheet R20
A1: SINOKOR DOCKING SHORE REPAIR REQUISITION FORM | H1: ← INDEX
A3: OWNER | C3: =INDEX!C2 -> SINOKOR MARITIME | E3: PREPARED BY
A4: VESSEL | C4: =INDEX!G2 -> SOUTH AFRICA PROSPERITY | E4: REQ. NO. | G4: R20
A5: EQUIPMENT | C5: DECK CRANE | E5: SERIAL NO.
A6: MAKER | E6: TYPE
A7: SUBJECT | C7: HH Crane, Provision Crane, ER Crane Health Check
A9: ITEM LIST
A10: No. | B10: JOB SCOPE | E10: UNIT | F10: Q.Ty | G10: REMARK
A11: 1 | B11: Hose handling crane health check | E11: Set | F11: 2 | G11: Maker
B12: Hose handling crane : Luffing Cylinder recondition & Rechroming (Based on Condition) | E12: Set | F12: 2 | G12: Seal replacement by Shipyard
B13: Hose Handling Crane : Hoisting Motor Overhauling (Based on condition) | E13: Set | F13: 2
B14: Hose handling Crane : Sheave Bearing replacement (Based on Condition) | E14: PCS
B15: Hydraulic Hose to be replaced | E15: set | F15: 2 | G15: Mandatory
B16: Control valve block to be overhauled | E16: Set | F16: 2
B17: * Spare should be prepared by service company (If necessary)
A19: 2 | B19: Provision Crane Health Check | E19: Set | F19: 2 | G19: Maker
B20: Provision crane : Luffing Cylinder recondition & Rechroming (Based on Condition) | E20: Set | F20: 2 | G20: Seal replacement by Shipyard
B21: Provision Crane : Hoisting Motor Overhauling (Based on condition : 2sets) | E21: Set | F21: 2
B22: Provision Crane : Sheave Bearing replacement (Based on Condition) | E22: PCS
B23: Hydraulic Hose to be replaced | E23: Set | F23: 2 | G23: Mandatory
B24: Control valve block to be overhauled | E24: Set | F24: 2
B25: * Spare should be prepared by service company (If necessary)
A27: 3 | B27: E/R Crane Health Check
A31: 13
A32: 14
A33: 15
A34: 16
A35: 17
A36: 18
A37: 19
A38: 20
A39: 21
A40: 22
A41: 23
A42: 24
... A48: 30

Sheet R21
A1: SINOKOR DOCKING SHORE REPAIR REQUISITION FORM | H1: ← INDEX
A3: OWNER | C3: =INDEX!C2 -> SINOKOR MARITIME | E3: PREPARED BY
A4: VESSEL | C4: =INDEX!G2 -> SOUTH AFRICA PROSPERITY | E4: REQ. NO. | G4: R21
A5: EQUIPMENT | C5: Hydraulic System | E5: SERIAL NO.
A6: MAKER | E6: TYPE
A7: SUBJECT | C7: Steering Gear Hydraulic System Health Check
A9: ITEM LIST
A10: No. | B10: JOB SCOPE | E10: UNIT | F10: Q.Ty | G10: REMARK
A11: 1 | B11: Overhual main hydraulic Pump for Steering Gear | E11: Set | F11: 2
A12: 2 | B12: Replace V packing of ram | E12: Set | F12: 4
A13: 3 | B13: Overhaul Servo pumps | E13: Set | F13: 2
A14: 4 | B14: Health check for the whole Steering gear System | E14: lot | F14: 1
A15: 5
A16: 6
A17: 7
A18: 8
A19: 9
A20: 10
A21: 11
A22: 12
A23: 13
A24: 14
A25: 15
A26: 16
... A40: 30

Sheet R22
A1: SINOKOR DOCKING SHORE REPAIR REQUISITION FORM | H1: ← INDEX
A3: OWNER | C3: =INDEX!C2 -> SINOKOR MARITIME | E3: PREPARED BY | G3: OWNER
A4: VESSEL | C4: =INDEX!G2 -> SOUTH AFRICA PROSPERITY | E4: REQ. NO. | G4: R22
A5: EQUIPMENT | C5: LSA & FFE | E5: SERIAL NO.
A6: MAKER | E6: TYPE
A7: SUBJECT | C7: LSA & FFE 5 Yearly Service
A9: ITEM LIST
A10: No. | B10: JOB SCOPE | E10: UNIT | F10: Q.Ty | G10: REMARK
A11: 1 | B11: 5 Yearly LSA & FFE Service to be provided | E11: Lot | F11: 1
A12: 2 | B12: BV Certificate to be provided
A13: 3 | B13: Job scope to be provided as per last LSA & FFE service report
A14: 4
A15: 5
A16: 6
A17: 7
A18: 8
A19: 9
A20: 10
A21: 11
A22: 12
A23: 13
A24: 14
A25: 15
... A40: 30

Sheet R23
A1: SINOKOR DOCKING SHORE REPAIR REQUISITION FORM | H1: ← INDEX
A3: OWNER | C3: =INDEX!C2 -> SINOKOR MARITIME | E3: PREPARED BY
A4: VESSEL | C4: =INDEX!G2 -> SOUTH AFRICA PROSPERITY | E4: REQ. NO. | G4: R23
A5: EQUIPMENT | E5: SERIAL NO.
A6: MAKER | E6: TYPE
A7: SUBJECT | C7: 5 Yearly Radia Survey
A9: ITEM LIST
A10: No. | B10: JOB SCOPE | E10: UNIT | F10: Q.Ty | G10: REMARK
A11: 1 | B11: Radio Survey : 5Yearly Special survey scope | E11: Lot | F11: 1
A12: 2 | B12: GMDSS Annual Service with BV Certificates | E12: Lot | F12: 1
A13: 3 | B13: VDR APT & Certificate issu | E13: Lot | F13: 1 | G13: Maker :
A14: 4 | B14: Radio Equipments & VDR reprogramming | E14: Lot | F14: 1
A15: 5
A16: 6
A17: 7
A18: 8
A19: 9
A20: 10
A21: 11
A22: 12
A23: 13
A24: 14
A25: 15
A26: 16
... A40: 30

Sheet R24
A1: SINOKOR DOCKING SHORE REPAIR REQUISITION FORM | H1: ← INDEX
A3: OWNER | C3: =INDEX!C2 -> SINOKOR MARITIME | E3: PREPARED BY | G3: OWNER
A4: VESSEL | C4: =INDEX!G2 -> SOUTH AFRICA PROSPERITY | E4: REQ. NO. | G4: R24
A5: EQUIPMENT | E5: SERIAL NO.
A6: MAKER | E6: TYPE
A7: SUBJECT | C7: Elevator Annual Service
A9: ITEM LIST
A10: No. | B10: JOB SCOPE | E10: UNIT | F10: Q.Ty | G10: REMARK
A11: 1 | B11: Elevator 5 Yearly Service to be provided according to Maker's scope | E11: Lot | F11: 1
A12: 2
A13: 3
A14: 4
A15: 5
A16: 6
A17: 7
A18: 8
A19: 9
A20: 10
A21: 11
A22: 12
A23: 13
... A40: 30

Sheet R25
A1: SINOKOR DOCKING SHORE REPAIR REQUISITION FORM | H1: ← INDEX
A3: OWNER | C3: =INDEX!C2 -> SINOKOR MARITIME | E3: PREPARED BY | G3: OWNER
A4: VESSEL | C4: =INDEX!G2 -> SOUTH AFRICA PROSPERITY | E4: REQ. NO. | G4: R25
A5: EQUIPMENT | C5: INERT GAS SYSTEM | E5: SERIAL NO.
A6: MAKER | C6: KASHIWA | E6: TYPE
A7: SUBJECT | C7: Inert Gas System Health Check
A9: ITEM LIST
A10: No. | B10: JOB SCOPE | E10: UNIT | F10: Q.Ty | G10: REMARK
A11: 1 | B11: Inert Gas System Health Check for 5yearly scope. | E11: LOT | F11: 1
A12: 2 | B12: If any issue, repair should be provided during DD. | G12: IF NECESSARY
A13: 3
A14: 4
A15: 5
A16: 6
A17: 7
A18: 8
A19: 9
A20: 10
A21: 11
A22: 12
A23: 13
A24: 14
... A40: 30

Sheet R26
A1: SINOKOR DOCKING SHORE REPAIR REQUISITION FORM | H1: ← INDEX
A3: OWNER | C3: =INDEX!C2 -> SINOKOR MARITIME | E3: PREPARED BY | G3: OWNER
A4: VESSEL | C4: =INDEX!G2 -> SOUTH AFRICA PROSPERITY | E4: REQ. NO. | G4: R26
A5: EQUIPMENT | C5: COPT & WBPT GOVERNOR | E5: SERIAL NO.
A6: MAKER | C6: WOODWARD | E6: TYPE | G6: PGD
A7: SUBJECT | C7: COPT & WBPT GOVERNOR OVERHAUL
A9: ITEM LIST
A10: No. | B10: JOB SCOPE | E10: UNIT | F10: Q.Ty | G10: REMARK
A11: 1 | B11: G/E GOVERNOR OVHL | E11: SET | F11: 4 | G11: COPT : 3 SETS // WBPT : 1SET
A12: 2 | B12: OVHL kit supply | E12: SET | F12: 4
A13: 3 | B13: Trial Running | E13: INCL.
A14: 4
A15: 5
A16: 6
A17: 7
A18: 8
A19: 9
A20: 10
A21: 11
A22: 12
A23: 13
A24: 14
A25: 15
... A40: 30

Sheet R27
A1: SINOKOR DOCKING SHORE REPAIR REQUISITION FORM | H1: ← INDEX
A3: OWNER | C3: =INDEX!C2 -> SINOKOR MARITIME | E3: PREPARED BY | G3: OWNER
A4: VESSEL | C4: =INDEX!G2 -> SOUTH AFRICA PROSPERITY | E4: REQ. NO. | G4: R27
A5: EQUIPMENT | C5: Windlass | E5: SERIAL NO.
A6: MAKER | E6: TYPE
A7: SUBJECT | C7: Windlass Hydraulic System Health Check
A9: ITEM LIST
A10: No. | B10: JOB SCOPE | E10: UNIT | F10: Q.Ty | G10: REMARK
A11: 1 | B11: Windlass Hydraulic System Health Check | E11: Set | F11: 2
A12: 2 | B12: Overhaul Control Valve Block (Based on Condition) | E12: Set | F12: 2
A13: 3 | B13: Adjust Hydraulic Brake Unit | E13: Set | F13: 2
A14: 4 | B14: Hydraulic Hose for brake to be replaced | E14: Set | F14: 2
A15: 5
A16: 6
A17: 7
A18: 8
A19: 9
A20: 10
A21: 11
A22: 12
A23: 13
A24: 14
A25: 15
A26: 16
... A40: 30

Sheet R28
A1: SINOKOR DOCKING SHORE REPAIR REQUISITION FORM | H1: ← INDEX
A3: OWNER | C3: =INDEX!C2 -> SINOKOR MARITIME | E3: PREPARED BY
A4: VESSEL | C4: =INDEX!G2 -> SOUTH AFRICA PROSPERITY | E4: REQ. NO. | G4: R28
A5: EQUIPMENT | E5: SERIAL NO.
A6: MAKER | E6: TYPE
A7: SUBJECT
A9: ITEM LIST
A10: No. | B10: JOB SCOPE | E10: UNIT | F10: Q.Ty | G10: REMARK
A11: 1
A12: 2
A13: 3
A14: 4
A15: 5
A16: 6
A17: 7
A18: 8
A19: 9
A20: 10
A21: 11
A22: 12
... A40: 30

Sheet R29
A1: SINOKOR DOCKING SHORE REPAIR REQUISITION FORM | H1: ← INDEX
A3: OWNER | C3: =INDEX!C2 -> SINOKOR MARITIME | E3: PREPARED BY
A4: VESSEL | C4: =INDEX!G2 -> SOUTH AFRICA PROSPERITY | E4: REQ. NO. | G4: R29
A5: EQUIPMENT | E5: SERIAL NO.
A6: MAKER | E6: TYPE
A7: SUBJECT
A9: ITEM LIST
A10: No. | B10: JOB SCOPE | E10: UNIT | F10: Q.Ty | G10: REMARK
A11: 1
A12: 2
A13: 3
A14: 4
A15: 5
A16: 6
A17: 7
A18: 8
A19: 9
A20: 10
A21: 11
A22: 12
... A40: 30

Sheet R30
A1: SINOKOR DOCKING SHORE REPAIR REQUISITION FORM | H1: ← INDEX
A3: OWNER | C3: =INDEX!C2 -> SINOKOR MARITIME | E3: PREPARED BY
A4: VESSEL | C4: =INDEX!G2 -> SOUTH AFRICA PROSPERITY | E4: REQ. NO. | G4: R30
A5: EQUIPMENT | E5: SERIAL NO.
A6: MAKER | E6: TYPE
A7: SUBJECT
A9: ITEM LIST
A10: No. | B10: JOB SCOPE | E10: UNIT | F10: Q.Ty | G10: REMARK
A11: 1
A12: 2
A13: 3
A14: 4
A15: 5
A16: 6
A17: 7
A18: 8
A19: 9
A20: 10
A21: 11
A22: 12
... A40: 30

Sheet R31
A1: SINOKOR DOCKING SHORE REPAIR REQUISITION FORM | H1: ← INDEX
A3: OWNER | C3: =INDEX!C2 -> SINOKOR MARITIME | E3: PREPARED BY
A4: VESSEL | C4: =INDEX!G2 -> SOUTH AFRICA PROSPERITY | E4: REQ. NO. | G4: R31
A5: EQUIPMENT | E5: SERIAL NO.
A6: MAKER | E6: TYPE
A7: SUBJECT
A9: ITEM LIST
A10: No. | B10: JOB SCOPE | E10: UNIT | F10: Q.Ty | G10: REMARK
A11: 1
A12: 2
A13: 3
A14: 4
A15: 5
A16: 6
A17: 7
A18: 8
A19: 9
A20: 10
A21: 11
A22: 12
... A40: 30

Sheet S1
A1: SINOKOR DOCKING SPARE PART REQUISITION FORM | I1: ← INDEX
A3: OWNER | C3: =INDEX!C2 -> SINOKOR MARITIME | F3: PREPARED BY | G3: OWNER
A4: VESSEL | C4: =INDEX!G2 -> SOUTH AFRICA PROSPERITY | F4: REQ. NO. | G4: S1
A5: EQUIPMENT | C5: MAIN ENGINE | F5: SERIAL NO.
A6: MAKER | C6: HYUNDAI MAN | F6: TYPE | G6: 6S90MC-C
A7: SUBJECT | C7: MAIN ENGINE OVHL SPARE
A9: ITEM LIST
A10: No. | B10: Part No. | C10: Description | F10: Unit | G10: Req. Q'ty | H10: Remark
C11: Cylinder Cover
A12: 1 | B12: P90101-0159, 079 | C12: O-Ring | F12: PCS | G12: =2*6 -> 12
A13: 2 | B13: P90101-0159, 126 | C13: Gasket | F13: PCS | G13: =1*6 -> 6
C14: Piston and Piston Rod
A15: 3 | B15: 90201-0225, 35 | C15: Piston ring No.1 | F15: PCS | G15: =1*6 -> 6
A16: 4 | B16: 90201-0225, 47 | C16: Piston ring No.2 | F16: PCS | G16: =1*6 -> 6
A17: 5 | B17: 90201-0225, 59 | C17: Piston ring No.3 | F17: PCS | G17: =1*6 -> 6
A18: 6 | B18: 90201-0225, 60 | C18: Piston ring No.4 | F18: PCS | G18: =1*6 -> 6
A19: 7 | B19: 90201-0225, 131 | C19: D-Ring | F19: PCS | G19: =1*6 -> 6
A20: 8 | B20: 90201-0225, 155 | C20: D-Ring | F20: PCS | G20: =1*6 -> 6
A21: 9 | B21: 90201-0225, 238 | C21: Sealing Ring | F21: PCS | G21: =12*6 -> 72
A22: 10 | B22: 90201-0225, 180 | C22: Locking Wire | F22: M | G22: 20
C23: Piston Rod Stuffing Box
A24: 11 | B24: 90205-0116, 108 | C24: O-Ring | F24: PCS | G24: =2*6 -> 12
A25: 12 | B25: 90205-0116, 204 | C25: Sealing Ring | F25: SET | G25: 1
A26: 13 | B26: 90205-0116, 170 | C26: Sealing Ring | F26: SET | G26: 2
A27: 14 | B27: 90205-0116, 145 | C27: Sealing Ring | F27: SET | G27: 2
A28: 15 | B28: 90205-0116, 253 | C28: Lamella | F28: SET | G28: =4*6 -> 24
C29: Cylinder Liner and Cooling Jacket
A30: 16 | B30: 90302-0618, 083 | C30: Piston Cleaning Ring | F30: PCS | G30: =1*6 -> 6
A31: 17 | B31: 90302-0618, 010 | C31: O-Ring | F31: PCS | G31: =2*6 -> 12
A32: 18 | B32: 90302-0618, 022 | C32: O-Ring | F32: PCS | G32: =1*6 -> 6
A33: 19 | B33: 90302-0618, 178 | C33: O-Ring | F33: PCS | G33: 50

Sheet S2
A1: SINOKOR DOCKING SPARE PART REQUISITION FORM | I1: ← INDEX
A3: OWNER | C3: =INDEX!C2 -> SINOKOR MARITIME | F3: PREPARED BY | G3: OWNER
A4: VESSEL | C4: =INDEX!G2 -> SOUTH AFRICA PROSPERITY | F4: REQ. NO. | G4: S2
A5: EQUIPMENT | C5: MAIN ENGINE | F5: SERIAL NO.
A6: MAKER | C6: HYUNDAI MAN | F6: TYPE | G6: 6S90MC-C
A7: SUBJECT | C7: M/E F.O PUMP OVHL SPARE
A9: ITEM LIST
A10: No. | B10: Part No. | C10: Description | F10: Unit | G10: Req. Q'ty | H10: Remark
C11: Fuel Pump
A12: 1 | B12: 90901-0210, 581 | C12: Sealing Ring | F12: PCS | G12: =1*6 -> 6
A13: 2 | B13: 90901-0210, 627 | C13: Packing | F13: PCS | G13: =1*6 -> 6
A14: 3 | B14: 90901-0210, 640 | C14: Sealing Ring | F14: PCS | G14: =1*6 -> 6
A15: 4 | B15: 90901-0210, 711 | C15: Sealing Ring | F15: PCS | G15: =1*6 -> 6
A16: 5 | B16: 90901-0210, 377 | C16: Sealing Ring | F16: PCS | G16: =1*6 -> 6
A17: 6 | B17: 90901-0210, 389 | C17: Sealing Ring | F17: PCS | G17: =1*6 -> 6
A18: 7 | B18: 90901-0210, 400 | C18: Sealing Ring | F18: PCS | G18: =2*6 -> 12
A19: 8 | B19: 90901-0210, 221 | C19: Packing | F19: PCS | G19: =1*6 -> 6
A20: 9 | B20: 90901-0210, 747 | C20: Suction Valve, Complete | F20: SET | G20: 1
A21: 10 | B21: 90901-0210, 424 | C21: Plunger Barrel , Complete | F21: SET | G21: 1
C22: Fuel Valve
A23: 11 | B23: 90910-0137, 197 | C23: O-Ring | F23: PCS | G23: =2*12 -> 24
A24: 12 | B24: 90910-0137, 124 | C24: O-Ring | F24: PCS | G24: =2*12 -> 24
A25: 13 | B25: 90910-0137, 173 | C25: O-Ring | F25: PCS | G25: =2*12 -> 24
A26: 14 | B26: 90910-0137, 244 | C26: Disc | F26: PCS | G26: 10
A27: 15 | B27: 90910-0137, 281 | C27: Thrust Foot | F27: PCS | G27: 4
A28: 16 | B28: 90910-0137, 268 | C28: Spring | F28: PCS | G28: 4
A29: 17 | B29: 90910-0137, 065 | C29: Spindle Guide, Complete | F29: SET | G29: 12
A30: 18
A31: 19
A32: 20
A33: 21
A34: 22
A35: 23
A36: 24
A37: 25
A38: 26
A39: 27
A40: 28

Sheet S3
A1: SINOKOR DOCKING SPARE PART REQUISITION FORM | I1: ← INDEX
A3: OWNER | C3: =INDEX!C2 -> SINOKOR MARITIME | F3: PREPARED BY | G3: OWNER
A4: VESSEL | C4: =INDEX!G2 -> SOUTH AFRICA PROSPERITY | F4: REQ. NO. | G4: S3
A5: EQUIPMENT | C5: MAIN ENGINE | F5: SERIAL NO.
A6: MAKER | C6: HYUNDAI MITSUBISHI | F6: TYPE | G6: MET71MA
A7: SUBJECT | C7: M/E T/C OVHL SPARE
A9: ITEM LIST
A10: No. | B10: Part No. | C10: Description | F10: Unit | G10: Req. Q'ty | H10: Remark
A11: 1 | B11: N/A | C11: 30,000H OVHL KIT | F11: SET | G11: 2
A12: 2
A13: 3
A14: 4
A15: 5
A16: 6
A17: 7
A18: 8
A19: 9
A20: 10
A21: 11
A22: 12
A23: 13
... A40: 30

Sheet S4
A1: SINOKOR DOCKING SPARE PART REQUISITION FORM | I1: ← INDEX
A3: OWNER | C3: =INDEX!C2 -> SINOKOR MARITIME | F3: PREPARED BY | G3: OWNER
A4: VESSEL | C4: =INDEX!G2 -> SOUTH AFRICA PROSPERITY | F4: REQ. NO. | G4: S4
A5: EQUIPMENT | C5: MAIN ENGINE | F5: SERIAL NO.
A6: MAKER | C6: HYUNDAI MAN | F6: TYPE | G6: 6S90MC-C
A7: SUBJECT | C7: M/E AIR COOLER SPARE
A9: ITEM LIST
A10: No. | B10: Part No. | C10: Description | F10: Unit | G10: Req. Q'ty | H10: Remark
A11: 1 | B11: 91005-0119, 056 | C11: O-ring | F11: SET | G11: 4
A12: 2
A13: 3
A14: 4
A15: 5
A16: 6
A17: 7
A18: 8
A19: 9
A20: 10
A21: 11
A22: 12
A23: 13
... A40: 30

Sheet S5
A1: SINOKOR DOCKING SPARE PART REQUISITION FORM | I1: ← INDEX
A3: OWNER | C3: =INDEX!C2 -> SINOKOR MARITIME | F3: PREPARED BY | G3: OWNER
A4: VESSEL | C4: =INDEX!G2 -> SOUTH AFRICA PROSPERITY | F4: REQ. NO. | G4: S5
A5: EQUIPMENT | C5: MAIN ENGINE | F5: SERIAL NO.
A6: MAKER | C6: HMMCO | F6: TYPE | G6: HYUNDAI MAN 6S90MC-C
A7: SUBJECT | C7: M/E AUX BLOWER SPARE
A9: ITEM LIST
A10: No. | B10: Part No. | C10: Description | F10: Unit | G10: Req. Q'ty | H10: Remark
A11: 1 | B11: H-REAR-01, 10 | C11: Sealing Ring | F11: PCS | G11: 2
A12: 2 | B12: H-REAR-01, 11 | C12: Gaslock Seal | F12: PCS | G12: 4
A13: 3 | B13: H-REAR-01, 08 | C13: Gasket | F13: PCS | G13: 2
A14: 4 | B14: H-REAR-01, 05 | C14: Gasket | F14: PCS | G14: 2
A15: 5
A16: 6
A17: 7
A18: 8
A19: 9
A20: 10
A21: 11
A22: 12
A23: 13
A24: 14
A25: 15
A26: 16
... A40: 30

Sheet S6
A1: SINOKOR DOCKING SPARE PART REQUISITION FORM | I1: ← INDEX
A3: OWNER | C3: =INDEX!C2 -> SINOKOR MARITIME | F3: PREPARED BY | G3: OWNER
A4: VESSEL | C4: =INDEX!G2 -> SOUTH AFRICA PROSPERITY | F4: REQ. NO. | G4: S6
A5: EQUIPMENT | C5: AUX ENGINE | F5: SERIAL NO.
A6: MAKER | C6: HYUNDAI HIMSEN | F6: TYPE | G6: 7H21/32
A7: SUBJECT | C7: AUX ENGINE OVHL SPARE
A9: ITEM LIST
A10: No. | B10: Part No. | C10: Description | F10: Unit | G10: Req. Q'ty | H10: Remark
C11: Cyliner Head
A12: 1 | B12: A21100, 903 | C12: O-Ring | F12: PCS | G12: 21 | J12: 1 | K12: =J12*7 -> 7 | L12: =K12*3 -> 21
A13: 2 | B13: A21100, 118 | C13: O-Ring | F13: PCS | G13: 42 | J13: 2 | K13: =J13*7 -> 14 | L13: =K13*3 -> 42
A14: 3 | B14: A21100, 119 | C14: O-Ring | F14: PCS | G14: 21 | J14: 1 | K14: =J14*7 -> 7 | L14: =K14*3 -> 21
A15: 4 | B15: A21100, 291 | C15: O-Ring | F15: PCS | G15: 84 | J15: 4 | K15: =J15*7 -> 28 | L15: =K15*3 -> 84
A16: 5 | B16: A21100, 111 | C16: Valve Insert - Inlet | F16: PCS | G16: 14 | J16: 2 | K16: =J16*7 -> 14 | L16: =K16*3 -> 42
A17: 6 | B17: A21100, 112 | C17: Valve Insert - Outlet | F17: PCS | G17: 14 | J17: 2 | K17: =J17*7 -> 14 | L17: =K17*3 -> 42
A18: 7 | B18: A21200, 201 | C18: Inlet valve spindle | F18: PCS | G18: 14 | J18: 2 | K18: =J18*7 -> 14 | L18: =K18*3 -> 42
A19: 8 | B19: A21200, 202 | C19: Exhaust valve spindle | F19: PCS | G19: 14 | J19: 2 | K19: =J19*7 -> 14 | L19: =K19*3 -> 42
A20: 9 | B20: A21200, 203 | C20: Spring | F20: PCS | G20: 8 | J20: 4 | K20: =J20*7 -> 28 | L20: =K20*3 -> 84
A21: 10 | B21: A21200, 204 | C21: Roto cap | F21: SET | G21: 28 | J21: 4 | K21: =J21*7 -> 28 | L21: =K21*3 -> 84
C22: Piston | K22: =J22*7 -> 0 | L22: =K22*3 -> 0
A23: 11 | B23: M31000, 151 | C23: Compression ring - Top | F23: PCS | G23: 21 | J23: 7 | K23: =J23 -> 7 | L23: =K23*3 -> 21
A24: 12 | B24: M31000, 152 | C24: Compression ring - 2nd | F24: PCS | G24: 21 | J24: 7 | K24: =J24 -> 7 | L24: =K24*3 -> 21
A25: 13 | B25: M31000, 153 | C25: Oil scraper ring | F25: PCS | G25: 21 | J25: 7 | K25: =J25 -> 7 | L25: =K25*3 -> 21
A26: 14 | B26: M31000, 116 | C26: O-Ring | F26: PCS | G26: 21 | J26: 7 | K26: =J26 -> 7 | L26: =K26*3 -> 21
C27: Connecting Rod | K27: =J27*7 -> 0 | L27: =K27*3 -> 0
A28: 15 | B28: A32000, 120 | C28: Big end bearing | F28: SET | G28: 21 | J28: 7 | K28: =J28 -> 7 | L28: =K28*3 -> 21
A29: 16 | B29: A32000, 130 | C29: Small end bearing | F29: SET | G29: 7 | J29: 7 | K29: =J29 -> 7 | L29: =K29*3 -> 21
A30: 17 | B30: A32000, 191 | C30: Sud for con-rod big end | F30: PCS | G30: 42 | J30: 2 | K30: =J30*7 -> 14 | L30: =K30*3 -> 42
C31: Cylinder Liner | K31: =J31*7 -> 0 | L31: =K31*3 -> 0
A32: 18 | B32: A15000, 901 | C32: O-Ring | F32: PCS | G32: 21 | J32: 1 | K32: =J32*7 -> 7 | L32: =K32*3 -> 21
A33: 19 | B33: A15000, 902 | C33: O-Ring | F33: PCS | G33: 21 | J33: 1 | K33: =J33*7 -> 7 | L33: =K33*3 -> 21
A34: 20 | B34: A15000, 907 | C34: O-Ring | F34: PCS | G34: 21 | J34: 1 | K34: =J34*7 -> 7 | L34: =K34*3 -> 21
A35: 21 | B35: A15000, 922 | C35: O-Ring | F35: PCS | G35: 21 | J35: 1 | K35: =J35*7 -> 7 | L35: =K35*3 -> 21
A36: 22 | B36: A15000, 923 | C36: O-Ring | F36: PCS | G36: 21 | J36: 1 | K36: =J36*7 -> 7 | L36: =K36*3 -> 21
A37: 23 | B37: A15000, 942 | C37: O-Ring | F37: PCS | G37: 21 | J37: 1 | K37: =J37*7 -> 7 | L37: =K37*3 -> 21
A38: 24 | B38: A15000, 943 | C38: O-Ring | F38: PCS | G38: 21 | J38: 1 | K38: =J38*7 -> 7 | L38: =K38*3 -> 21
A39: 25 | B39: A15000, 122 | C39: Flame Ring | F39: PCS | G39: 7 | J39: 1 | K39: =J39*7 -> 7 | L39: =K39*3 -> 21
A40: 26 | B40: A15000, 191 | C40: Sealing ring | F40: PCS | G40: 21 | J40: 1 | K40: =J40*7 -> 7 | L40: =K40*3 -> 21
A41: 27 | B41: A15000, 192 | C41: O-Ring | F41: PCS | G41: 21 | J41: 1 | K41: =J41*7 -> 7 | L41: =K41*3 -> 21
A42: 28 | B42: A15000, 193 | C42: O-Ring | F42: PCS | G42: 21 | J42: 1 | K42: =J42*7 -> 7 | L42: =K42*3 -> 21
...

Sheet S7
A1: SINOKOR DOCKING SPARE PART REQUISITION FORM | I1: ← INDEX
A3: OWNER | C3: =INDEX!C2 -> SINOKOR MARITIME | F3: PREPARED BY | G3: OWNER
A4: VESSEL | C4: =INDEX!G2 -> SOUTH AFRICA PROSPERITY | F4: REQ. NO. | G4: S7
A5: EQUIPMENT | C5: AUX ENGINE | F5: SERIAL NO. | G5: HT514005
A6: MAKER | C6: ABB | F6: TYPE | G6: TPS52D01
A7: SUBJECT | C7: AUX ENGINE T/C OVHL SPARE
A9: ITEM LIST
A10: No. | B10: Part No. | C10: Description | F10: Unit | G10: Req. Q'ty | H10: Remark
A11: 1 | C11: 12,000H OVHL KIT | F11: SET | G11: 3
A12: 2 | B12: 56001 | C12: Nozzle Ring | F12: SET | G12: 3 | H12: IMO No. TA70TT14
A13: 3
A14: 4
A15: 5
A16: 6
A17: 7
A18: 8
A19: 9
A20: 10
A21: 11
A22: 12
A23: 13
A24: 14
... A40: 30

Sheet S8
A1: SINOKOR DOCKING SPARE PART REQUISITION FORM | I1: ← INDEX
A3: OWNER | C3: =INDEX!C2 -> SINOKOR MARITIME | F3: PREPARED BY | G3: OWNER
A4: VESSEL | C4: =INDEX!G2 -> SOUTH AFRICA PROSPERITY | F4: REQ. NO. | G4: S8
A5: EQUIPMENT | C5: STERN TUBE | F5: SERIAL NO. | G5: X-39128
A6: MAKER | C6: KEMEL | F6: TYPE | G6: AX-900
A7: SUBJECT | C7: STERN TUBE SPARE
A9: ITEM LIST
A10: No. | B10: Part No. | C10: Description | F10: Unit | G10: Req. Q'ty | H10: Remark
A11: 1 | C11: 5 YEAR OVHL KIT | F11: SET | G11: 1
A12: 2
A13: 3
A14: 4
A15: 5
A16: 6
A17: 7
A18: 8
A19: 9
A20: 10
A21: 11
A22: 12
A23: 13
... A40: 30

Sheet S9
A1: SINOKOR DOCKING SPARE PART REQUISITION FORM | I1: ← INDEX
A3: OWNER | C3: =INDEX!C2 -> SINOKOR MARITIME | F3: PREPARED BY | G3: OWNER
A4: VESSEL | C4: =INDEX!G2 -> SOUTH AFRICA PROSPERITY | F4: REQ. NO. | G4: S9
A5: EQUIPMENT | C5: ICCP & MGPS | F5: SERIAL NO. | G5: 5234/A
A6: MAKER | C6: KC | F6: TYPE | G6: AFT KCIT 790A / FWD KCIT 720A
A7: SUBJECT | C7: ICCP & MGPS SPARE
A9: ITEM LIST
A10: No. | B10: Part No. | C10: Description | F10: Unit | G10: Req. Q'ty | H10: Remark
C11: ICCP
A12: 1 | B12: IASTA21 | C12: 225 AMPERE MMO/Ti STRIPE ANODE ASSEMBLY | F12: SET | G12: 4
A13: 2 | B13: IACR16 | C13: 100 AMPERE MMO/Ti CIRCULAR ANODE ASSEMBLY | F13: SET | G13: 2
A14: 3 | B14: IREA21-1 | C14: PURITY ZINC REFERENCE ELECTRODE CELL ASSEMBLY FOR AFT | F14: SET | G14: 2
A15: 4 | B15: IREF22-1 | C15: PURITY ZINC REFERENCE ELECTRODE CELL ASSEMBLY FOR FWD | F15: SET | G15: 2
C16: MGPS
A17: 1 | B17: KFCU 800 | C17: CU (Copper) | F17: PCS | G17: 2
A18: 2 | B18: KFAL 800 | C18: AL (Aluminium) | F18: PCS | G18: 2

Sheet S10
A1: SINOKOR DOCKING SPARE PART REQUISITION FORM | I1: ← INDEX
A3: OWNER | C3: =INDEX!C2 -> SINOKOR MARITIME | F3: PREPARED BY | G3: OWNER
A4: VESSEL | C4: =INDEX!G2 -> SOUTH AFRICA PROSPERITY | F4: REQ. NO. | G4: S10
A5: EQUIPMENT | C5: AUX BOILER | F5: SERIAL NO.
A6: MAKER | C6: AALBOG | F6: TYPE | G6: MISSION D-TYPE
A7: SUBJECT | C7: AUX BOILER SPARE
A9: ITEM LIST
A10: No. | B10: Part No. | C10: Description | F10: Unit | G10: Req. Q'ty | H10: Remark
C11: BOILER
A12: 1 | B12: SITRANS P, TYPE 7MF4433 | C12: DP Transmitter | F12: SET | G12: 2
A13: 2 | B13: SIPART PS2 6DR5000 | C13: Positioner, SIPART | F13: SET | G13: 2
A14: 3 | B14: QRB1A-A050B70A2 | C14: Frame Detector (Photoresistive Detectors) | F14: PCS | G14: 1
C15: BURNER
A16: 4 | B16: 92Y : 056718, 1 | C16: Nozzle | F16: PCS | G16: 1
A17: 5 | B17: 92Y : 056718, 2 | C17: O-Ring | F17: PCS | G17: 10
A18: 6 | B18: 92Y : 056718, 3 | C18: Gasket | F18: PCS | G18: 10
C19: IGNITION BURNER
A20: 7 | B20: 92Z99:028368, 2 | C20: Nozzle | F20: EA | G20: 1
A21: 8 | B21: 92Z99:028368, 3 | C21: Set Electrode | F21: SET | G21: 1
A22: 9 | B22: 92Z99:028368, F166 | C22: Transformer | F22: EA | G22: 1

Sheet S11
A1: SINOKOR DOCKING SPARE PART REQUISITION FORM | I1: ← INDEX
A3: OWNER | C3: =INDEX!C2 -> SINOKOR MARITIME | F3: PREPARED BY | G3: OWNER
A4: VESSEL | C4: =INDEX!G2 -> SOUTH AFRICA PROSPERITY | F4: REQ. NO. | G4: S11
A5: EQUIPMENT | C5: CARGO VALVE | F5: SERIAL NO. | G5: H2308
A6: MAKER | C6: ACE VALVE | F6: TYPE | G6: BUTTERFLY VALVE
A7: SUBJECT | C7: CARGO VALVE SPARE
A9: ITEM LIST
A10: No. | B10: Part No. | C10: Description | F10: Unit | G10: Req. Q'ty | H10: Remark
A11: 1 | B11: 10K 250A | C11: SEAT | F11: EA | G11: 4
A12: 2 | B12: 10K 500A | C12: SEAT | F12: EA | G12: 2
A13: 3 | B13: 10K 550A | C13: SEAT | F13: EA | G13: 4
A14: 4 | B14: 16K 200A | C14: SEAT | F14: EA | G14: 2
A15: 5 | B15: 16K 300A | C15: SEAT | F15: EA | G15: 2
A16: 6 | B16: 16K 550A | C16: SEAT | F16: EA | G16: 4
A17: 7 | B17: 16K 600A | C17: SEAT | F17: EA | G17: 2
A18: 8 | B18: 16K 700A | C18: SEAT | F18: EA | G18: 2
A19: 9 | B19: 16K 750A | C19: SEAT | F19: EA | G19: 2
A20: 10
A21: 11
A22: 12
A23: 13
A24: 14
A25: 15
A26: 16
A27: 17
A28: 18
A29: 19
A30: 20
A31: 21
... A40: 30

Sheet S12
A1: SINOKOR DOCKING SPARE PART REQUISITION FORM | I1: ← INDEX
A3: OWNER | C3: =INDEX!C2 -> SINOKOR MARITIME | F3: PREPARED BY | G3: OWNER
A4: VESSEL | C4: =INDEX!G2 -> SOUTH AFRICA PROSPERITY | F4: REQ. NO. | G4: S12
A5: EQUIPMENT | C5: IG VALVE | F5: SERIAL NO.
A6: MAKER | F6: TYPE
A7: SUBJECT | C7: IG VALVE SPARE
A9: ITEM LIST
A10: No. | B10: Part No. | C10: Description | F10: Unit | G10: Req. Q'ty | H10: Remark
A11: 1
A12: 2
A13: 3
A14: 4
A15: 5
A16: 6
A17: 7
A18: 8
A19: 9
A20: 10
A21: 11
A22: 12
... A40: 30

Sheet S13
A1: SINOKOR DOCKING SPARE PART REQUISITION FORM | I1: ← INDEX
A3: OWNER | C3: =INDEX!C2 -> SINOKOR MARITIME | F3: PREPARED BY | G3: OWNER
A4: VESSEL | C4: =INDEX!G2 -> SOUTH AFRICA PROSPERITY | F4: REQ. NO. | G4: S13
A5: EQUIPMENT | C5: PV VALVE | F5: SERIAL NO. | G5: HULL NO. 2308
A6: MAKER | C6: SEWON | F6: TYPE | G6: NSD+HPV TYPE
A7: SUBJECT | C7: PV VALVE SPARE
A9: ITEM LIST
A10: No. | B10: Part No. | C10: Description | F10: Unit | G10: Req. Q'ty | H10: Remark
A11: 1 | B11: SW-NSD-A, 13 | C11: SCREEN (30 MESH X SWG NO.34) | F11: PCS | G11: 18
A12: 2 | B12: SW-HPV-ISO-A, 11 | C12: SCREEN (30 MESH X SWG NO.34) | F12: PCS | G12: 1
A13: 3
A14: 4
A15: 5
A16: 6
A17: 7
A18: 8
A19: 9
A20: 10
A21: 11
A22: 12
A23: 13
A24: 14
... A40: 30

Sheet S14
A1: SINOKOR DOCKING SPARE PART REQUISITION FORM | I1: ← INDEX
A3: OWNER | C3: =INDEX!C2 -> SINOKOR MARITIME | F3: PREPARED BY | G3: OWNER
A4: VESSEL | C4: =INDEX!G2 -> SOUTH AFRICA PROSPERITY | F4: REQ. NO. | G4: S14
A5: EQUIPMENT | C5: HOSE HANDELING CRANE | F5: SERIAL NO.
A6: MAKER | C6: ORIENTAL | F6: TYPE | G6: HHC640-2021
A7: SUBJECT | C7: HOSE HANDELING CRANE SPARE
A9: ITEM LIST
A10: No. | B10: Part No. | C10: Description | F10: Unit | G10: Req. Q'ty | H10: Remark
A11: 1 | B11: 20 TON | C11: HYD. HOSE FULL SET | F11: SET | G11: 2
A12: 2
A13: 3
A14: 4
A15: 5
A16: 6
A17: 7
A18: 8
A19: 9
A20: 10
A21: 11
A22: 12
A23: 13
... A40: 30

Sheet S15
A1: SINOKOR DOCKING SPARE PART REQUISITION FORM | I1: ← INDEX
A3: OWNER | C3: =INDEX!C2 -> SINOKOR MARITIME | F3: PREPARED BY | G3: OWNER
A4: VESSEL | C4: =INDEX!G2 -> SOUTH AFRICA PROSPERITY | F4: REQ. NO. | G4: S15
A5: EQUIPMENT | C5: PROVISION CRANE | F5: SERIAL NO.
A6: MAKER | C6: ORIENTAL | F6: TYPE | G6: HPC280-1018, HPC120-0321
A7: SUBJECT | C7: PROVISION CRANE SPARE
A9: ITEM LIST
A10: No. | B10: Part No. | C10: Description | F10: Unit | G10: Req. Q'ty | H10: Remark
A11: 1 | C11: HYD. HOSE FULL SET | F11: SET | G11: 2
A12: 2
A13: 3
A14: 4
A15: 5
A16: 6
A17: 7
A18: 8
A19: 9 | B19: 3 TON | C19: HYD. HOSE FULL SET | F19: SET | G19: 1
A20: 10 | B20: 10 TON | C20: HYD. HOSE FULL SET | F20: SET | G20: 1
A21: 11
A22: 12
A23: 13
A24: 14
A25: 15
A26: 16
A27: 17
A28: 18
A29: 19
A30: 20
A31: 21
A32: 22
... A40: 30

Sheet S16
A1: SINOKOR DOCKING SPARE PART REQUISITION FORM | I1: ← INDEX
A3: OWNER | C3: =INDEX!C2 -> SINOKOR MARITIME | F3: PREPARED BY | G3: OWNER
A4: VESSEL | C4: =INDEX!G2 -> SOUTH AFRICA PROSPERITY | F4: REQ. NO. | G4: S16
A5: EQUIPMENT | C5: E/R PUMP | F5: SERIAL NO.
A6: MAKER | C6: SHINKO | F6: TYPE
A7: SUBJECT | C7: E/R PUMP SPARE
A9: ITEM LIST
A10: No. | B10: Part No. | C10: Description | F10: Unit | G10: Req. Q'ty | H10: Remark
C11: NO.1 MAIN COOL. S.W PUMP | H11: MODEL : SVA300MS
A12: 1 | B12: C-125600MA, 38 | C12: Mouth Ring | F12: EA | G12: 2
A13: 2 | B13: C-125600MA, 41 | C13: Line Bearing | F13: EA | G13: 1
A14: 3 | B14: C-125600MA, 54 | C14: M/Seal | F14: SET | G14: 1
A15: 4 | B15: C-125600MA, 59 | C15: Zinc Plate | F15: EA | G15: 2
A16: 5 | B16: C-125600MA, 60 | C16: Packing | F16: EA | G16: 1
A17: 6 | B17: C-125600MA, 60A | C17: Packing | F17: EA | G17: 1
C18: NO.2 MAIN COOL. S.W PUMP | H18: MODEL : SVA300M
A19: 7 | B19: C-125600MA, 38 | C19: Mouth Ring | F19: EA | G19: 2
A20: 8 | B20: C-125600MA, 41 | C20: Line Bearing | F20: EA | G20: 1
A21: 9 | B21: C-125600MA, 54 | C21: M/Seal | F21: SET | G21: 1
A22: 10 | B22: C-125600MA, 59 | C22: Zinc Plate | F22: EA | G22: 2
A23: 11 | B23: C-125600MA, 60 | C23: Packing | F23: EA | G23: 1
A24: 12 | B24: C-125600MA, 60A | C24: Packing | F24: EA | G24: 1
C25: NO.2 MAIN COOL. S.W PUMP | H25: MODEL : SVA300AM
A26: 13 | B26: C-125600MA, 38 | C26: Mouth Ring | F26: EA | G26: 2
A27: 14 | B27: C-125600MA, 41 | C27: Line Bearing | F27: EA | G27: 1
A28: 15 | B28: C-125600MA, 54 | C28: M/Seal | F28: SET | G28: 1
A29: 16 | B29: C-125600MA, 59 | C29: Zinc Plate | F29: EA | G29: 2
A30: 17 | B30: C-125600MA, 60 | C30: Packing | F30: EA | G30: 1
A31: 18 | B31: C-125600MA, 60A | C31: Packing | F31: EA | G31: 1
C32: COPT COND COOLING PUMP | H32: MODEL : SVA400M
A33: 19 | B33: C-126000MA, 38 | C33: Mouth Ring | F33: EA | G33: 2
A34: 20 | B34: C-126000MA, 41 | C34: Line Bearing | F34: EA | G34: 1
A35: 21 | B35: C-126000MA, 54 | C35: M/Seal | F35: SET | G35: 1
A36: 22 | B36: C-126000MA, 59 | C36: Zinc Plate | F36: EA | G36: 2
A37: 23 | B37: C-126000MA, 60 | C37: Packing | F37: EA | G37: 1
A38: 24 | B38: C-126000MA, 60A | C38: Packing | F38: EA | G38: 1
C39: AUX. COOL. S.W PUMP | H39: MODEL : SVA250M
A40: 25 | B40: C-125600MA, 38 | C40: Mouth Ring | F40: EA | G40: 2
A41: 26 | B41: C-125600MA, 41 | C41: Line Bearing | F41: EA | G41: 1
A42: 27 | B42: C-125600MA, 54 | C42: M/Seal | F42: SET | G42: 1
...

Sheet S17
A1: SINOKOR DOCKING SPARE PART REQUISITION FORM | I1: ← INDEX
A3: OWNER | C3: =INDEX!C2 -> SINOKOR MARITIME | F3: PREPARED BY | G3: OWNER
A4: VESSEL | C4: =INDEX!G2 -> SOUTH AFRICA PROSPERITY | F4: REQ. NO. | G4: S17
A5: EQUIPMENT | C5: FIXED GAS DETECTION SYSTEM | F5: SERIAL NO.
A6: MAKER | C6: CONSILIUM | F6: TYPE | G6: SW2020
A7: SUBJECT | C7: FIXED GAS DETECTION SYSTEM SPARE
A9: ITEM LIST
A10: No. | B10: Part No. | C10: Description | F10: Unit | G10: Req. Q'ty | H10: Remark
A11: 1 | B11: 107 CCD20 | C11: Vaccum pump | F11: SET | G11: 1
A12: 2 | B12: BUTOX ST400EC | C12: H2S Gas Detector | F12: PCS | G12: 1
A13: 3 | B13: BUTOX ST400EC | C13: O2 Gas Detector | F13: PCS | G13: 1
A14: 4 | B14: SALWICO GD10 | C14: C3H8 Gas Detector | F14: PCS | G14: 1
A15: 5
A16: 6
A17: 7
A18: 8
A19: 9
A20: 10
A21: 11
A22: 12
A23: 13
A24: 14
A25: 15
A26: 16
... A40: 30

Sheet S18
A1: SINOKOR DOCKING SPARE PART REQUISITION FORM | I1: ← INDEX
A3: OWNER | C3: =INDEX!C2 -> SINOKOR MARITIME | F3: PREPARED BY
A4: VESSEL | C4: =INDEX!G2 -> SOUTH AFRICA PROSPERITY | F4: REQ. NO. | G4: S18
A5: EQUIPMENT | C5: EGCS | F5: SERIAL NO.
A6: MAKER | F6: TYPE
A7: SUBJECT | C7: EGCS SPARE
A9: ITEM LIST
A10: No. | B10: Part No. | C10: Description | F10: Unit | G10: Req. Q'ty | H10: Remark
A11: 1
A12: 2
A13: 3
A14: 4
A15: 5
A16: 6
A17: 7
A18: 8
A19: 9
A20: 10
A21: 11
A22: 12
... A40: 30

Sheet S19
A1: SINOKOR DOCKING SPARE PART REQUISITION FORM | I1: ← INDEX
A3: OWNER | C3: =INDEX!C2 -> SINOKOR MARITIME | F3: PREPARED BY | G3: MANAGER
A4: VESSEL | C4: =INDEX!G2 -> SOUTH AFRICA PROSPERITY | F4: REQ. NO. | G4: S19
A5: EQUIPMENT | C5: PRINTERS FOR NAVTEX AND DGPS | F5: SERIAL NO.
A6: MAKER | C6: JRC | F6: TYPE | G6: NAVTEX : NCR 333 // DGPS : NKG-84 & JLR 7800
A7: SUBJECT | C7: SPARES FOR BRIDGE EQUIPMENT
A9: ITEM LIST
A10: No. | B10: Part No. | C10: Description | F10: Unit | G10: Req. Q'ty | H10: Remark
A11: 1
A12: 2 | C12: Printer GPU-414 for Navtex JRC NCR-333 | F12: PCS | G12: 1
A13: 3 | C13: DGPS Printer JRC NKG-84 for DGPS JRC JLR-7800 | F13: PCS | G13: 1
A14: 4 | H14: OFFER RECEIVED FROM DAN MARINE 774,86 USD
A15: 5 | H15: OFFER RECEIVED FROM ANCHOMARINE GROUP 1334,56 USD
A16: 6 | H16: OFFER RECEIVED FROM WEIJA MARINE 819 USD
A17: 7
A18: 8
A19: 9
A20: 10
A21: 11
A22: 12
A23: 13
A24: 14
A25: 15
A26: 16
A27: 17
A28: 18
... A40: 30

Sheet S20
A1: SINOKOR DOCKING SPARE PART REQUISITION FORM | I1: ← INDEX
A3: OWNER | C3: =INDEX!C2 -> SINOKOR MARITIME | F3: PREPARED BY
A4: VESSEL | C4: =INDEX!G2 -> SOUTH AFRICA PROSPERITY | F4: REQ. NO. | G4: S20
A5: EQUIPMENT | F5: SERIAL NO.
A6: MAKER | F6: TYPE
A7: SUBJECT
A9: ITEM LIST
A10: No. | B10: Part No. | C10: Description | F10: Unit | G10: Req. Q'ty | H10: Remark
A11: 1
A12: 2
A13: 3
A14: 4
A15: 5
A16: 6
A17: 7
A18: 8
A19: 9
A20: 10
A21: 11
A22: 12
... A40: 30

Sheet S21
A1: SINOKOR DOCKING SPARE PART REQUISITION FORM | I1: ← INDEX
A3: OWNER | C3: =INDEX!C2 -> SINOKOR MARITIME | F3: PREPARED BY
A4: VESSEL | C4: =INDEX!G2 -> SOUTH AFRICA PROSPERITY | F4: REQ. NO. | G4: S21
A5: EQUIPMENT | F5: SERIAL NO.
A6: MAKER | F6: TYPE
A7: SUBJECT
A9: ITEM LIST
A10: No. | B10: Part No. | C10: Description | F10: Unit | G10: Req. Q'ty | H10: Remark
A11: 1
A12: 2
A13: 3
A14: 4
A15: 5
A16: 6
A17: 7
A18: 8
A19: 9
A20: 10
A21: 11
A22: 12
... A40: 30

Sheet S22
A1: SINOKOR DOCKING SPARE PART REQUISITION FORM | I1: ← INDEX
A3: OWNER | C3: =INDEX!C2 -> SINOKOR MARITIME | F3: PREPARED BY
A4: VESSEL | C4: =INDEX!G2 -> SOUTH AFRICA PROSPERITY | F4: REQ. NO. | G4: S22
A5: EQUIPMENT | F5: SERIAL NO.
A6: MAKER | F6: TYPE
A7: SUBJECT
A9: ITEM LIST
A10: No. | B10: Part No. | C10: Description | F10: Unit | G10: Req. Q'ty | H10: Remark
A11: 1
A12: 2
A13: 3
A14: 4
A15: 5
A16: 6
A17: 7
A18: 8
A19: 9
A20: 10
A21: 11
A22: 12
... A40: 30

Sheet S23
A1: SINOKOR DOCKING SPARE PART REQUISITION FORM | I1: ← INDEX
A3: OWNER | C3: =INDEX!C2 -> SINOKOR MARITIME | F3: PREPARED BY
A4: VESSEL | C4: =INDEX!G2 -> SOUTH AFRICA PROSPERITY | F4: REQ. NO. | G4: S23
A5: EQUIPMENT | F5: SERIAL NO.
A6: MAKER | F6: TYPE
A7: SUBJECT
A9: ITEM LIST
A10: No. | B10: Part No. | C10: Description | F10: Unit | G10: Req. Q'ty | H10: Remark
A11: 1
A12: 2
A13: 3
A14: 4
A15: 5
A16: 6
A17: 7
A18: 8
A19: 9
A20: 10
A21: 11
A22: 12
... A40: 30

Sheet S24
A1: SINOKOR DOCKING SPARE PART REQUISITION FORM | I1: ← INDEX
A3: OWNER | C3: =INDEX!C2 -> SINOKOR MARITIME | F3: PREPARED BY
A4: VESSEL | C4: =INDEX!G2 -> SOUTH AFRICA PROSPERITY | F4: REQ. NO. | G4: S24
A5: EQUIPMENT | F5: SERIAL NO.
A6: MAKER | F6: TYPE
A7: SUBJECT
A9: ITEM LIST
A10: No. | B10: Part No. | C10: Description | F10: Unit | G10: Req. Q'ty | H10: Remark
A11: 1
A12: 2
A13: 3
A14: 4
A15: 5
A16: 6
A17: 7
A18: 8
A19: 9
A20: 10
A21: 11
A22: 12
... A40: 30

Sheet S25
A1: SINOKOR DOCKING SPARE PART REQUISITION FORM | I1: ← INDEX
A3: OWNER | C3: =INDEX!C2 -> SINOKOR MARITIME | F3: PREPARED BY
A4: VESSEL | C4: =INDEX!G2 -> SOUTH AFRICA PROSPERITY | F4: REQ. NO. | G4: S25
A5: EQUIPMENT | F5: SERIAL NO.
A6: MAKER | F6: TYPE
A7: SUBJECT
A9: ITEM LIST
A10: No. | B10: Part No. | C10: Description | F10: Unit | G10: Req. Q'ty | H10: Remark
A11: 1
A12: 2
A13: 3
A14: 4
A15: 5
A16: 6
A17: 7
A18: 8
A19: 9
A20: 10
A21: 11
A22: 12
... A40: 30

Sheet S26
A1: SINOKOR DOCKING SPARE PART REQUISITION FORM | I1: ← INDEX
A3: OWNER | C3: =INDEX!C2 -> SINOKOR MARITIME | F3: PREPARED BY
A4: VESSEL | C4: =INDEX!G2 -> SOUTH AFRICA PROSPERITY | F4: REQ. NO. | G4: S26
A5: EQUIPMENT | F5: SERIAL NO.
A6: MAKER | F6: TYPE
A7: SUBJECT
A9: ITEM LIST
A10: No. | B10: Part No. | C10: Description | F10: Unit | G10: Req. Q'ty | H10: Remark
A11: 1
A12: 2
A13: 3
A14: 4
A15: 5
A16: 6
A17: 7
A18: 8
A19: 9
A20: 10
A21: 11
A22: 12
... A40: 30

Sheet S27
A1: SINOKOR DOCKING SPARE PART REQUISITION FORM | I1: ← INDEX
A3: OWNER | C3: =INDEX!C2 -> SINOKOR MARITIME | F3: PREPARED BY
A4: VESSEL | C4: =INDEX!G2 -> SOUTH AFRICA PROSPERITY | F4: REQ. NO. | G4: S27
A5: EQUIPMENT | F5: SERIAL NO.
A6: MAKER | F6: TYPE
A7: SUBJECT
A9: ITEM LIST
A10: No. | B10: Part No. | C10: Description | F10: Unit | G10: Req. Q'ty | H10: Remark
A11: 1
A12: 2
A13: 3
A14: 4
A15: 5
A16: 6
A17: 7
A18: 8
A19: 9
A20: 10
A21: 11
A22: 12
... A40: 30

Sheet S28
A1: SINOKOR DOCKING SPARE PART REQUISITION FORM | I1: ← INDEX
A3: OWNER | C3: =INDEX!C2 -> SINOKOR MARITIME | F3: PREPARED BY
A4: VESSEL | C4: =INDEX!G2 -> SOUTH AFRICA PROSPERITY | F4: REQ. NO. | G4: S28
A5: EQUIPMENT | F5: SERIAL NO.
A6: MAKER | F6: TYPE
A7: SUBJECT
A9: ITEM LIST
A10: No. | B10: Part No. | C10: Description | F10: Unit | G10: Req. Q'ty | H10: Remark
A11: 1
A12: 2
A13: 3
A14: 4
A15: 5
A16: 6
A17: 7
A18: 8
A19: 9
A20: 10
A21: 11
A22: 12
... A40: 30

Sheet S29
A1: SINOKOR DOCKING SPARE PART REQUISITION FORM | I1: ← INDEX
A3: OWNER | C3: =INDEX!C2 -> SINOKOR MARITIME | F3: PREPARED BY
A4: VESSEL | C4: =INDEX!G2 -> SOUTH AFRICA PROSPERITY | F4: REQ. NO. | G4: S29
A5: EQUIPMENT | F5: SERIAL NO.
A6: MAKER | F6: TYPE
A7: SUBJECT
A9: ITEM LIST
A10: No. | B10: Part No. | C10: Description | F10: Unit | G10: Req. Q'ty | H10: Remark
A11: 1
A12: 2
A13: 3
A14: 4
A15: 5
A16: 6
A17: 7
A18: 8
A19: 9
A20: 10
A21: 11
A22: 12
... A40: 30

Sheet S30
A1: SINOKOR DOCKING SPARE PART REQUISITION FORM | I1: ← INDEX
A3: OWNER | C3: =INDEX!C2 -> SINOKOR MARITIME | F3: PREPARED BY
A4: VESSEL | C4: =INDEX!G2 -> SOUTH AFRICA PROSPERITY | F4: REQ. NO. | G4: S30
A5: EQUIPMENT | F5: SERIAL NO.
A6: MAKER | F6: TYPE
A7: SUBJECT
A9: ITEM LIST
A10: No. | B10: Part No. | C10: Description | F10: Unit | G10: Req. Q'ty | H10: Remark
A11: 1
A12: 2
A13: 3
A14: 4
A15: 5
A16: 6
A17: 7
A18: 8
A19: 9
A20: 10
A21: 11
A22: 12
... A40: 30

Sheet ST1
A1: SINOKOR DOCKING STORE REQUISITION FORM | I1: ← INDEX
A3: OWNER | C3: =INDEX!C2 -> SINOKOR MARITIME | F3: PREPARED BY | G3: OWNER
A4: VESSEL | C4: =INDEX!G2 -> SOUTH AFRICA PROSPERITY | F4: REQ. NO. | G4: ST1
A5: EQUIPMENT | C5: ENGINE | F5: SERIAL NO.
A6: MAKER | F6: TYPE
A7: SUBJECT | C7: WIRE
A9: ITEM LIST
A10: No. | B10: Part No. | C10: Description | F10: Unit | G10: Req. Q'ty | H10: Remark
C11: HOSE HANDLING CRANE
A12: 1 | C12: WIRE ROPE (⌀18(35×7)-270M = 28.7 TON, G.S.W.R) | F12: SET | G12: 2
C13: PROVISION CRANE
A14: 2 | C14: WIRE ROPE (⌀18(35×7)-145M = 28.1 TON, G.S.W.R) | F14: SET | G14: 2
C15: LIFE BOAT
A16: 3 | C16: WIRE ROPE (⌀16 Non-Twist Type with galvanized, 92 M) | F16: SET | G16: 2
A17: 4 | C17: WIRE ROPE (⌀16 Non-Twist Type with galvanized, 85 M) | F17: SET | G17: 2
C18: ACCOMMODATION LADDER
A19: 5 | C19: WIRE ROPE (⌀14 (6X24) 100 M) | F19: SET | G19: 2

Sheet ST2
A1: SINOKOR DOCKING STORE REQUISITION FORM | I1: ← INDEX
A3: OWNER | C3: =INDEX!C2 -> SINOKOR MARITIME | F3: PREPARED BY | G3: OWNER
A4: VESSEL | C4: =INDEX!G2 -> SOUTH AFRICA PROSPERITY | F4: REQ. NO. | G4: ST2
A5: EQUIPMENT | C5: ENGINE | F5: SERIAL NO.
A6: MAKER | F6: TYPE
A7: SUBJECT | C7: BRAKE LINING
A9: ITEM LIST
